Workbook

Sheet Data Set
A1: Product_ID | B1: Product_Name | C1: Category | D1: Supplier_Name | E1: Order_Date | F1: Delivery_Date | G1: Stock_Quantity | H1: Reorder_Level | I1: Units_Sold | J1: Purchase_Cost | K1: Selling_Price | L1: Warehouse_Location | M1: Shipping_Time_Days | N1: Total_Revenue | O1: Total_Profit | P1: Stock Available_vs_Units Sold | Q1: Delivery_Delay | R1: Delay_Status
A2: PROD1000 | B2: Tablet | C2: Fashion | D2: Supplier D | E2: 45140 | F2: 45145 | G2: 3 | H2: 59 | I2: 241 | J2: 1800 | K2: 2081 | L2: Chennai | M2: 5 | N2: =I2*K2 -> 501521 | O2: =K2-J2 -> 281 | P2: =IF(G2>I2,"Overstock",IF(G2<I2,"Understock","Balanced")) -> Understock | Q2: =(F2-E2)-M2 -> 0 | R2: =IF(Q2>0,"Delayed",IF(Q2=0,"On Time","Early")) -> On Time
A3: PROD1001 | B3: Tablet | C3: Fashion | D3: Supplier D | E3: 45393 | F3: 45395 | G3: 118 | H3: 105 | I3: 70 | J3: 1950 | K3: 2169 | L3: Hyderabad | M3: 2 | N3: =I3*K3 -> 151830 | O3: =K3-J3 -> 219 | P3: =IF(G3>I3,"Overstock",IF(G3<I3,"Understock","Balanced")) -> Overstock | Q3: =(F3-E3)-M3 -> 0 | R3: =IF(Q3>0,"Delayed",IF(Q3=0,"On Time","Early")) -> On Time
A4: PROD1002 | B4: Mixer | C4: Sports | D4: Supplier A | E4: 45520 | F4: 45524 | G4: 57 | H4: 108 | I4: 107 | J4: 828 | K4: 1322 | L4: Bangalore | M4: 4 | N4: =I4*K4 -> 141454 | O4: =K4-J4 -> 494 | P4: =IF(G4>I4,"Overstock",IF(G4<I4,"Understock","Balanced")) -> Understock | Q4: =(F4-E4)-M4 -> 0 | R4: =IF(Q4>0,"Delayed",IF(Q4=0,"On Time","Early")) -> On Time
A5: PROD1003 | B5: TV | C5: Sports | D5: Supplier B | E5: 45626 | F5: 45628 | G5: 420 | H5: 129 | I5: 271 | J5: 317 | K5: 598 | L5: Chennai | M5: 2 | N5: =I5*K5 -> 162058 | O5: =K5-J5 -> 281 | P5: =IF(G5>I5,"Overstock",IF(G5<I5,"Understock","Balanced")) -> Overstock | Q5: =(F5-E5)-M5 -> 0 | R5: =IF(Q5>0,"Delayed",IF(Q5=0,"On Time","Early")) -> On Time
A6: PROD1004 | B6: Mixer | C6: Fashion | D6: Supplier C | E6: 45507 | F6: 45515 | G6: 401 | H6: 77 | I6: 210 | J6: 645 | K6: 1061 | L6: Mumbai | M6: 8 | N6: =I6*K6 -> 222810 | O6: =K6-J6 -> 416 | P6: =IF(G6>I6,"Overstock",IF(G6<I6,"Understock","Balanced")) -> Overstock | Q6: =(F6-E6)-M6 -> 0 | R6: =IF(Q6>0,"Delayed",IF(Q6=0,"On Time","Early")) -> On Time
A7: PROD1005 | B7: Laptop | C7: Home Appliances | D7: Supplier B | E7: 45166 | F7: 45176 | G7: 188 | H7: 103 | I7: 236 | J7: 833 | K7: 1296 | L7: Delhi | M7: 10 | N7: =I7*K7 -> 305856 | O7: =K7-J7 -> 463 | P7: =IF(G7>I7,"Overstock",IF(G7<I7,"Understock","Balanced")) -> Understock | Q7: =(F7-E7)-M7 -> 0 | R7: =IF(Q7>0,"Delayed",IF(Q7=0,"On Time","Early")) -> On Time
A8: PROD1006 | B8: Laptop | C8: Fashion | D8: Supplier A | E8: 45502 | F8: 45505 | G8: 173 | H8: 58 | I8: 190 | J8: 1026 | K8: 1180 | L8: Bangalore | M8: 3 | N8: =I8*K8 -> 224200 | O8: =K8-J8 -> 154 | P8: =IF(G8>I8,"Overstock",IF(G8<I8,"Understock","Balanced")) -> Understock | Q8: =(F8-E8)-M8 -> 0 | R8: =IF(Q8>0,"Delayed",IF(Q8=0,"On Time","Early")) -> On Time
A9: PROD1007 | B9: Mixer | C9: Home Appliances | D9: Supplier B | E9: 45187 | F9: 45197 | G9: 184 | H9: 140 | I9: 76 | J9: 896 | K9: 1370 | L9: Delhi | M9: 10 | N9: =I9*K9 -> 104120 | O9: =K9-J9 -> 474 | P9: =IF(G9>I9,"Overstock",IF(G9<I9,"Understock","Balanced")) -> Overstock | Q9: =(F9-E9)-M9 -> 0 | R9: =IF(Q9>0,"Delayed",IF(Q9=0,"On Time","Early")) -> On Time
A10: PROD1008 | B10: Camera | C10: Sports | D10: Supplier E | E10: 45012 | F10: 45021 | G10: 158 | H10: 122 | I10: 29 | J10: 1318 | K10: 1751 | L10: Delhi | M10: 9 | N10: =I10*K10 -> 50779 | O10: =K10-J10 -> 433 | P10: =IF(G10>I10,"Overstock",IF(G10<I10,"Understock","Balanced")) -> Overstock | Q10: =(F10-E10)-M10 -> 0 | R10: =IF(Q10>0,"Delayed",IF(Q10=0,"On Time","Early")) -> On Time
A11: PROD1009 | B11: TV | C11: Electronics | D11: Supplier E | E11: 45092 | F11: 45096 | G11: 473 | H11: 147 | I11: 115 | J11: 1680 | K11: 2001 | L11: Chennai | M11: 4 | N11: =I11*K11 -> 230115 | O11: =K11-J11 -> 321 | P11: =IF(G11>I11,"Overstock",IF(G11<I11,"Understock","Balanced")) -> Overstock | Q11: =(F11-E11)-M11 -> 0 | R11: =IF(Q11>0,"Delayed",IF(Q11=0,"On Time","Early")) -> On Time
A12: PROD1010 | B12: Mixer | C12: Home Appliances | D12: Supplier C | E12: 45106 | F12: 45111 | G12: 131 | H12: 150 | I12: 256 | J12: 1258 | K12: 1365 | L12: Bangalore | M12: 5 | N12: =I12*K12 -> 349440 | O12: =K12-J12 -> 107 | P12: =IF(G12>I12,"Overstock",IF(G12<I12,"Understock","Balanced")) -> Understock | Q12: =(F12-E12)-M12 -> 0 | R12: =IF(Q12>0,"Delayed",IF(Q12=0,"On Time","Early")) -> On Time
A13: PROD1011 | B13: Shoes | C13: Home Appliances | D13: Supplier C | E13: 45111 | F13: 45114 | G13: 150 | H13: 100 | I13: 250 | J13: 565 | K13: 880 | L13: Delhi | M13: 3 | N13: =I13*K13 -> 220000 | O13: =K13-J13 -> 315 | P13: =IF(G13>I13,"Overstock",IF(G13<I13,"Understock","Balanced")) -> Understock | Q13: =(F13-E13)-M13 -> 0 | R13: =IF(Q13>0,"Delayed",IF(Q13=0,"On Time","Early")) -> On Time
... A15001: PROD15999 | B15001: Tablet | C15001: Sports | D15001: Supplier C | E15001: 45048 | F15001: 45049 | G15001: 444 | H15001: 143 | I15001: 113 | J15001: 1000 | K15001: 1234 | L15001: Bangalore | M15001: 1 | N15001: =I15001*K15001 -> 139442 | O15001: =K15001-J15001 -> 234 | P15001: =IF(G15001>I15001,"Overstock",IF(G15001<I15001,"Understock","Balanced")) -> Overstock | Q15001: =(F15001-E15001)-M15001 -> 0 | R15001: =IF(Q15001>0,"Delayed",IF(Q15001=0,"On Time","Early")) -> On Time

Sheet Data Analysis
A3: 1.Total Units Sold : | C3: =SUM('Data Set'!I1:I150010) -> 2222508
A5: 2.Total Revenue (Units Sold × Selling Price) : | C5: =SUM('Data Set'!N2:N15001) -> 3076312144
A7: 3.Total Profit (Selling Price - Purchase Cost) : | C7: =SUM('Data Set'!O2:O15001) -> 4136961
A9: 4.Average Shipping Time : | C9: =AVERAGE('Data Set'!M2:M15001) -> 5.4961333
A11: 5.Stock Available vs Units Sold | B11: Overstock : | C11: =COUNTIF('Data Set'!P:P,"Overstock") -> 10524
B12: Understock : | C12: =COUNTIF('Data Set'!P:P,"Understock") -> 4452
B13: Balanced : | C13: =COUNTIF('Data Set'!P:P,"Balanced") -> 24

Sheet Business Insights
A2: 1.Identify overstock and understock products
B5: Row Labels | C5: Count of Stock Available vs Units Sold
B6: AC | C6: 1471
B7: Camera | C7: 1566
B8: Fan | C8: 1508
B9: Laptop | C9: 1544
B10: Mixer | C10: 1531
B11: Phone | C11: 1498
B12: Shoes | C12: 1413
B13: Tablet | C13: 1519
B14: TV | C14: 1476
B15: Watch | C15: 1474
B16: Grand Total | C16: 15000
A26: 2.Find fast-moving vs slow-moving products
B28: Row Labels | C28: Sum of Units_Sold
B29: Camera | C29: 240401
B30: Laptop | C30: 227840
B31: Mixer | C31: 226878
B32: Tablet | C32: 222857
B33: Phone | C33: 220936
B34: Fan | C34: 220851
B35: Watch | C35: 219547
B36: AC | C36: 218074
B37: TV | C37: 217051
B38: Shoes | C38: 208073
B39: Grand Total | C39: 2222508
A48: 3.Analyze supplier performance :
B51: Row Labels | C51: Sum of Units_Sold | D51: Sum of Total Revenue | E51: Sum of Total Profit | F51: Average of Shipping_Time_Days
B52: Supplier A | C52: 447389 | D52: 615799968 | E52: 839954 | F52: 5.4816529
B53: Supplier B | C53: 442191 | D53: 617037930 | E53: 820321 | F53: 5.5201342
B54: Supplier C | C54: 448597 | D54: 614328940 | E54: 835548 | F54: 5.3925049
B55: Supplier D | C55: 431563 | D55: 598461560 | E55: 807143 | F55: 5.5438179
B56: Supplier E | C56: 452768 | D56: 630683746 | E56: 833995 | F56: 5.5450316
B57: Grand Total | C57: 2222508 | D57: 3076312144 | E57: 4136961 | F57: 5.4961333
A84: 4.Calculate delivery delays :
B87: Row Labels | C87: Sum of Total Profit
B88: AC | C88: 401785
B89: Camera | C89: 435216
B90: Fan | C90: 417841
B91: Laptop | C91: 423010
...
